<?xml version="1.0"?>
<robot xmlns:xacro="http://www.ros.org/wiki/xacro" name="new_gurdy_drive">

    <gazebo>
        <plugin name="gazebo_ros_control" filename="libgazebo_ros_control.so">
            <robotNamespace>/new_gurdy</robotNamespace>
        </plugin>
    </gazebo>

    <!--MACROS-->

    <xacro:macro name="aux_link" params="number x y z r p yaw">
        <link name="aux_${number}_link">
            <inertial>
                <origin xyz="0 0 0.0285" rpy="0 0 0"/>
                <mass value="0.01" />
                <inertia ixx="2.64583333333e-08" ixy="0.0" ixz="0.0" iyy="2.64583333333e-08" iyz="0.0" izz="1.125e-08"/>
            </inertial>
            <collision>
                <origin xyz="0 0 0.00285" rpy="0 0 0"/>
                <geometry>
                    <cylinder length="0.005" radius="0.0015"/>
                </geometry>
            </collision>
            <visual>
                <origin rpy="0.0 0 0" xyz="0 0 0"/>
                <geometry>
                    <cylinder length="0.005" radius="0.0015"/>
                </geometry>
                <material name="blue"/>
            </visual>
	    </link>
        <joint name="head_aux_${number}_joint" type="revolute">
            <parent link="head_link"/>
            <child link="aux_${number}_link"/>
            <origin xyz="${x} ${y} ${z}" rpy="${r} ${p} ${yaw}"/>
            <limit lower="-1.55" upper="1.55" effort="1.0" velocity="0.005"/>
            <axis xyz="0 0 1"/>
        </joint>
    </xacro:macro>


    <xacro:macro name="upperleg_link" params="number">
        <link name="upperleg_M${number}_link">
            <inertial>
                <origin xyz="0 0 0.03" rpy="0 0 0"/>
                <mass value="0.01" />
                <inertia ixx="3.015625e-05" ixy="0.0" ixz="0.0" iyy="3.015625e-05" iyz="0.0" izz="3.125e-07"/>
            </inertial>
            <collision>
                <origin xyz="0 0 0.03" rpy="0 0 0"/>
                <geometry>
                    <cylinder length="0.06" radius="0.0025"/>
                </geometry>
            </collision>
            <visual>
                <origin rpy="0.0 0 0" xyz="0 0 0"/>
                <geometry>
                    <mesh filename="package://gurdy_description/models/gurdy/meshes/gurdy_higherleg_v2.dae"/>
                </geometry>
            </visual>
        </link>
        <joint name="auxs_upperlegM${number}_joint" type="revolute">
            <parent link="aux_${number}_link"/>
            <child link="upperleg_M${number}_link"/>
            <origin xyz="0 0 0" rpy="0 0 0"/>
            <limit lower="-1.55" upper="0.0" effort="1.0" velocity="0.005"/>
            <axis xyz="0 1 0"/>
	    </joint>
    </xacro:macro>



    <xacro:macro name="lowerleg_link"  params="number">
        <link name="lowerleg_M${number}_link">
            <inertial>
                <origin xyz="0 0 0.03" rpy="0 0 0"/>
                <mass value="0.01" />
                <inertia ixx="3.005625e-05" ixy="0.0" ixz="0.0" iyy="3.005625e-05" iyz="0.0" izz="1.125e-07"/>
            </inertial>
            <collision>
                <origin xyz="0 0 0.03" rpy="0 0 0"/>
                <geometry>
                    <cylinder length="0.06" radius="0.0015"/>
                </geometry>
            </collision>
            <visual>
                <origin rpy="0.0 0 0" xyz="0 0 0"/>
                <geometry>
                    <mesh filename="package://gurdy_description/models/gurdy/meshes/gurdy_lowerleg_v2.dae"/>
                </geometry>
            </visual>
        </link>
        <joint name="upperlegM${number}_lowerlegM${number}_joint" type="continuous">
            <parent link="upperleg_M${number}_link"/>
            <child link="lowerleg_M${number}_link"/>
             <origin xyz="0 0.0095 0.06" rpy="0 0 3.14159"/>
            <limit lower="-2.9" upper="1.5708" effort="1.0" velocity="0.005"/>
            <axis xyz="0 1 0"/>
        </joint>
    </xacro:macro>

    <xacro:macro name="internallowerleg_link" params="number">
        <link name="internallowerleg_M${number}_link">
            <inertial>
                <origin xyz="0 0 0.03" rpy="0 0 0"/>
                <mass value="0.01" />
                <inertia ixx="5.58333333333e-06" ixy="0.0" ixz="0.0" iyy="5.58333333333e-06" iyz="0.0" izz="5e-07"/>
            </inertial>
            <collision>
                <origin xyz="0 0 0.03" rpy="0 0 0"/>
                <geometry>
                    <cylinder length="0.08" radius="0.001"/>
                </geometry>
            </collision>
            <visual>
                <origin rpy="0.0 0 0" xyz="0 0 0"/>
                <geometry>
                    <cylinder length="0.03" radius="0.001"/>
                </geometry>
                <material name="blue"/>
            </visual>
        </link>
        <joint name="internal_lowerleg${number}_joint" type="prismatic">
            <parent link="lowerleg_M${number}_link"/>
            <child link="internallowerleg_M${number}_link"/>
            <origin xyz="0 0.0 0.06" rpy="0 0 0"/>
            <limit lower="0" upper="0.02" effort="1.0" velocity="0.005"/>
            <axis xyz="0 0 1"/>
	    </joint>
    </xacro:macro>


    <xacro:macro name="foot_link" params="number colour">
        <link name="footM${number}_link">
            <inertial>
                <origin xyz="0 0 0" rpy="0 0 0"/>
                <mass value="0.01" />
                <inertia ixx="1.28e-06" ixy="0.0" ixz="0.0" iyy="1.28e-06" iyz="0.0" izz="1.28e-06"/>
            </inertial>
            <collision>
                <origin xyz="0 0 0" rpy="0 0 0"/>
                <geometry>
                    <sphere radius="0.008"/>
                </geometry>
            </collision>
            <visual>
                <origin rpy="0.0 0 0" xyz="0 0 0"/>
                <geometry>
                    <sphere radius="0.008"/>
                </geometry>
            </visual>
        </link>
        <gazebo reference="footM${number}_link">
            <kp>1000.0</kp>
            <kd>1000.0</kd>
            <mu1>10.0</mu1>
            <mu2>10.0</mu2>
            <material>Gazebo/${colour}</material>
        </gazebo>
        <joint name="basefoot_peg_M${number}_joint" type="continuous">
            <parent link="internallowerleg_M${number}_link"/>
            <child link="footM${number}_link"/>
            <origin xyz="0 0 0.02" rpy="0 0 0"/>
        </joint>
    </xacro:macro>


 <!-- Writing the xacro of transmissions -->

    <xacro:macro name="head_transmission" params="number number_transm">

        <transmission name="tran${number_transm}">
            <type>transmission_interface/SimpleTransmission</type>
            <joint name="head_aux_${number}_joint">
                <hardwareInterface>EffortJointInterface</hardwareInterface>
            </joint>
            <actuator name="motor${number_transm}">
                <hardwareInterface>EffortJointInterface</hardwareInterface>
                <mechanicalReduction>1</mechanicalReduction>
            </actuator>
        </transmission>
    </xacro:macro>


    <xacro:macro name="aux_transmission" params="number number_transm">

        <transmission name="tran${number_transm}">
            <type>transmission_interface/SimpleTransmission</type>
            <joint name="auxs_upperlegM${number}_joint">
                <hardwareInterface>EffortJointInterface</hardwareInterface>
            </joint>
            <actuator name="motor${number_transm}">
                <hardwareInterface>EffortJointInterface</hardwareInterface>
                <mechanicalReduction>1</mechanicalReduction>
            </actuator>
        </transmission>
    </xacro:macro>


    <xacro:macro name="intermediate_transmission" params="number number_transm">

        <transmission name="tran${number_transm}">
            <type>transmission_interface/SimpleTransmission</type>
            <joint name="upperlegM${number}_lowerlegM${number}_joint">
                <hardwareInterface>EffortJointInterface</hardwareInterface>
            </joint>
            <actuator name="motor${number_transm}">
                <hardwareInterface>EffortJointInterface</hardwareInterface>
                <mechanicalReduction>1</mechanicalReduction>
            </actuator>
        </transmission>
    </xacro:macro>


    <xacro:macro name="prismatic_transmission" params="number number_transm">

        <transmission name="tran${number_transm}">
            <type>transmission_interface/SimpleTransmission</type>
            <joint name="internal_lowerleg${number}_joint">
                <hardwareInterface>EffortJointInterface</hardwareInterface>
            </joint>
            <actuator name="motor${number_transm}">
                <hardwareInterface>EffortJointInterface</hardwareInterface>
                <mechanicalReduction>1</mechanicalReduction>
            </actuator>
        </transmission>
    </xacro:macro>


     <xacro:macro name="base_transmission" params="number number_transm">

        <transmission name="tran${number_transm}">
            <type>transmission_interface/SimpleTransmission</type>
            <joint name="basefoot_peg_M${number}_joint">
                <hardwareInterface>EffortJointInterface</hardwareInterface>
            </joint>
            <actuator name="motor${number_transm}">
                <hardwareInterface>EffortJointInterface</hardwareInterface>
                <mechanicalReduction>1</mechanicalReduction>
            </actuator>
        </transmission>
    </xacro:macro>

    <material name="blue">
        <color rgba="0 0 0.8 1"/>
    </material>
    <material name="red">
        <color rgba="0.8 0 0 1"/>
    </material>
    <material name="green">
        <color rgba="0 0.8 0 1"/>
    </material>


    <!-- *** Link Definitions *** -->

    <link name="base_link">
        <collision>
            <origin xyz="0 0 0" rpy="0 0 0"/>
            <geometry>
                <box size="0.01 0.01 0.01"/>
            </geometry>
        </collision>
		<visual>
		    <origin xyz="0 0 0.01" rpy="0 0 0"/>
			<geometry>
				<box size="0.01 0.01 0.01"/>
			</geometry>
		</visual>
	</link>

    <link name="head_link">
 	    <inertial>
            <origin xyz="0 0 0.02" rpy="0 0 0"/>
            <mass value="0.01" />
            <inertia ixx="7.58333333333e-07" ixy="0.0" ixz="0.0" iyy="7.58333333333e-07" iyz="0.0" izz="1.25e-06"/>
        </inertial>
        <collision>
            <origin xyz="0 0 0.02" rpy="0 0 0"/>
            <geometry>
                <cylinder radius="0.05" length="0.04"/>
            </geometry>
        </collision>
        <visual>
            <origin rpy="0.0 0 0" xyz="0 0 0"/>
            <geometry>
                <mesh filename="package://gurdy_description/models/gurdy/meshes/gurdy_head_v2.dae"/>
            </geometry>
        </visual>
	</link>

    <gazebo reference="head_link">
        <mu1>10.0</mu1>
        <mu2>10.0</mu2>
    </gazebo>

    <joint name="fixed" type="fixed">
        <parent link="base_link"/>
        <child link="head_link"/>
    </joint>


    <link name="antenna_link">
 	    <inertial>
            <origin xyz="0 0 0.05" rpy="0 0 0"/>
            <mass value="0.005" />
            <inertia ixx="3.01322916667e-06" ixy="0.0" ixz="0.0" iyy="3.01322916667e-06" iyz="0.0" izz="5.625e-09"/>
        </inertial>
        <collision>
            <origin xyz="0 0 0.05" rpy="0 0 0"/>
            <geometry>
                <cylinder length="0.085" radius="0.0015"/>
            </geometry>
        </collision>
        <visual>
            <origin rpy="0.0 0 0" xyz="0 0 0"/>
            <geometry>
                <cylinder length="0.085" radius="0.0015"/>
            </geometry>
            <material name="green"/>
        </visual>
	</link>


    <joint name="antenna_joint" type="fixed">
    	<parent link="head_link"/>
    	<child link="antenna_link"/>
        <origin xyz="0.0 0.0 0.051" rpy="0.0 0.785 0.0"/>
	</joint>


<!--Assign number values to the links/transmission -->

    <xacro:aux_link number="1" x="-0.02165" y="-0.0125" z="-0.008" r="3.145159" p="0" yaw="0.523599"/>
    <xacro:head_transmission number="1" number_transm="1"/>

    <xacro:aux_link number="2" x="0.02165" y="-0.0125" z="-0.008" r="3.145159" p="0" yaw="02.61799"/>
    <xacro:head_transmission number="2" number_transm="2"/>

    <xacro:aux_link number="3" x="0" y="0.025" z="-0.008" r="3.145159" p="0" yaw="0.523599"/>
    <xacro:head_transmission number="3" number_transm="3"/>



    <xacro:upperleg_link number="1" />
    <xacro:aux_transmission number="1" number_transm="4"/>

    <xacro:upperleg_link number="2"/>
    <xacro:aux_transmission number="2" number_transm="5"/>

    <xacro:upperleg_link number="3"/>
    <xacro:aux_transmission number="3" number_transm="6"/>



    <xacro:lowerleg_link number="1"/>
    <xacro:intermediate_transmission number="1" number_transm="7"/>

    <xacro:lowerleg_link number="2"/>
    <xacro:intermediate_transmission number="2" number_transm="8"/>

    <xacro:lowerleg_link number="3"/>
    <xacro:intermediate_transmission number="3" number_transm="9"/>




    <xacro:internallowerleg_link number="1"/>
    <xacro:prismatic_transmission number="1" number_transm="10"/>

    <xacro:internallowerleg_link number="2"/>
    <xacro:prismatic_transmission number="2" number_transm="11"/>

    <xacro:internallowerleg_link number="3"/>
    <xacro:prismatic_transmission number="3" number_transm="12"/>



    <xacro:foot_link number="1" colour="Blue"/>
    <xacro:base_transmission number="1" number_transm="13"/>

    <xacro:foot_link number="2" colour="Blue"/>
    <xacro:base_transmission number="2" number_transm="14"/>

    <xacro:foot_link number="3" colour="Green"/>
    <xacro:base_transmission number="3" number_transm="15"/>



<!-- Including the sensors IMU & Camera -->

    <gazebo>
        <plugin name="gazebo_ros_imu_controller" filename="libgazebo_ros_imu.so">
          <robotNamespace>/gurdy</robotNamespace>
          <topicName>imu/data</topicName>
          <serviceName>imu/service</serviceName>
          <bodyName>base_link</bodyName>
          <gaussianNoise>0</gaussianNoise>
          <rpyOffsets>0 0 0</rpyOffsets>
          <updateRate>5.0</updateRate>
          <alwaysOn>true</alwaysOn>
          <gaussianNoise>0</gaussianNoise>
        </plugin>
    </gazebo>


    <gazebo reference="camera_link">
        <sensor type="camera" name="camera1">
        <update_rate>15.0</update_rate>
        <camera name="head">

            <pose>0 0 0.05 0 0.785 0</pose>

            <horizontal_fov>1.3962634</horizontal_fov>
            <image>
            <width>400</width>
            <height>400</height>
            <format>R8G8B8</format>
            </image>
            <clip>
            <near>0.01</near>
            <far>100</far>
            </clip>
            <noise>
            <type>gaussian</type>
            <stddev>0.007</stddev>
            </noise>
        </camera>
        <plugin name="camera_controller" filename="libgazebo_ros_camera.so">
            <alwaysOn>true</alwaysOn>
            <updateRate>0.0</updateRate>
            <cameraName>gurdy/camera1</cameraName>
            <imageTopicName>image_raw</imageTopicName>
            <cameraInfoTopicName>camera_info</cameraInfoTopicName>
            <frameName>camera_link</frameName>
            <hackBaseline>0.07</hackBaseline>
            <distortionK1>0.0</distortionK1>
            <distortionK2>0.0</distortionK2>
            <distortionK3>0.0</distortionK3>
            <distortionT1>0.0</distortionT1>
            <distortionT2>0.0</distortionT2>
        </plugin>
        </sensor>
    </gazebo>

    <!-- Differential drive controller  -->
  <gazebo>
    <plugin name="differential_drive_controller" filename="libgazebo_ros_diff_drive.so">

      <rosDebugLevel>Debug</rosDebugLevel>
      <publishWheelTF>false</publishWheelTF>
      <robotNamespace>/new_gurdy_drive</robotNamespace>
      <publishTf>1</publishTf>
      <publishWheelJointState>false</publishWheelJointState>
      <alwaysOn>true</alwaysOn>
      <updateRate>100.0</updateRate>
      <leftJoint>basefoot_peg_M1_joint</leftJoint>
      <rightJoint>basefoot_peg_M2_joint</rightJoint>
      <wheelSeparation>${2*0.05}</wheelSeparation>
      <wheelDiameter>${2*0.008}</wheelDiameter>
      <broadcastTF>1</broadcastTF>
      <wheelTorque>30</wheelTorque>
      <wheelAcceleration>1.8</wheelAcceleration>
      <commandTopic>cmd_vel</commandTopic>
      <odometryFrame>odom</odometryFrame>
      <odometryTopic>odom</odometryTopic>
      <robotBaseFrame>base_link</robotBaseFrame>
      <legacyMode>false</legacyMode>
      <odometrySource>world</odometrySource> <!-- 'encoder' instead of 'world' is also possible -->
      <publishTf>1</publishTf>

    </plugin>
  </gazebo>



</robot>