<robot name="jibo">

    <material name="blue">
        <color rgba="0 0 0.8 1"/>
    </material>
    <material name="red">
        <color rgba="0.8 0 0 1"/>
    </material>
    <material name="green">
        <color rgba="0 0.8 0 1"/>
    </material>
	<!-- * * * Link Definitions * * * -->

    <link name="base_link">
        <inertial>
            <origin xyz="0 0 0.02" rpy="0 0 0"/>
            <mass value="2" />
            <inertia ixx="0.0116666666667" ixy="0.0" ixz="0.0" iyy="0.0116666666667" iyz="0.0" izz="0.0225"/>
        </inertial>
        <collision>
            <origin xyz="0 0 0" rpy="0 0 0"/>
            <geometry>
                <cylinder radius="0.15" length="0.05"/>
            </geometry>
        </collision>
		<visual>
		    <origin xyz="0 0 0.01" rpy="0 0 0"/>
			<geometry>
				<mesh filename="package://jibo_robot_description/models/jibo/meshes/jibo_final_parts_base_v3.dae"/>
			</geometry>
            <material name="blue"/>
		</visual>
	</link>

    <link name="yaw1_aux_link">
 	    <inertial>
            <origin xyz="0 0 0.0285" rpy="0 0 0"/>
            <mass value="0.01" />
            <inertia ixx="2.64583333333e-08" ixy="0.0" ixz="0.0" iyy="2.64583333333e-08" iyz="0.0" izz="1.125e-08"/>
        </inertial>
        <collision>
            <origin xyz="0 0 0.00285" rpy="0 0 0"/>
            <geometry>
                <cylinder radius="0.01" length="0.01"/>
            </geometry>
        </collision>
        <visual>
            <origin rpy="0.0 0 0" xyz="0 0 0"/>
            <geometry>
                <cylinder radius="0.01" length="0.01"/>
            </geometry>
            <material name="blue"/>
        </visual>
	</link>

    <joint name="base_yaw_joint" type="revolute">
    	<parent link="base_link"/>
    	<child link="yaw1_aux_link"/>
        <origin xyz="0.0 0.0 0.005" rpy="0.0 0.0 0.0"/>
        <limit effort="1.0" lower="-0.5" upper="0.5" velocity="0.5"/>
        <axis xyz="0 0 1"/>
	</joint>

    <gazebo>
        <plugin name="gazebo_ros_control" filename="libgazebo_ros_control.so">
        </plugin>
    </gazebo>

    <transmission name="tran1">
        <type>transmission_interface/SimpleTransmission</type>
        <joint name="base_yaw_joint">
            <hardwareInterface>EffortJointInterface</hardwareInterface>
        </joint>
        <actuator name="motor1">
            <hardwareInterface>EffortJointInterface</hardwareInterface>
            <mechanicalReduction>1</mechanicalReduction>
        </actuator>
    </transmission>

    <link name="fix_aux_link">
 	    <inertial>
            <origin xyz="0 0 0.0285" rpy="0 0 0"/>
            <mass value="0.01" />
            <inertia ixx="2.64583333333e-08" ixy="0.0" ixz="0.0" iyy="2.64583333333e-08" iyz="0.0" izz="1.125e-08"/>
        </inertial>
        <collision>
            <origin xyz="0 0 0.00285" rpy="0 0 0"/>
            <geometry>
                <cylinder radius="0.01" length="0.01"/>
            </geometry>
        </collision>
        <visual>
            <origin rpy="0.0 0 0" xyz="0 0 0"/>
            <geometry>
                <cylinder radius="0.01" length="0.01"/>
            </geometry>
            <material name="blue"/>
        </visual>
	</link>

    <joint name="yaw_fix_joint" type="fixed">
    	<parent link="yaw1_aux_link"/>
    	<child link="fix_aux_link"/>
        <origin xyz="0.0 0.0 0.0005" rpy="0.0 0.0 0.0"/>
	</joint>

    <link name="waist_link">
 	    <inertial>
            <origin xyz="0 0 0.005" rpy="0 0 0"/>
            <mass value="2" />
            <inertia ixx="0.0136166666667" ixy="0.0" ixz="0.0" iyy="0.0136166666667" iyz="0.0" izz="0.0256"/>
        </inertial>
        <collision>
            <origin xyz="0 0 0.005" rpy="0 0 0"/>
            <geometry>
                <cylinder radius="0.16" length="0.07"/>
            </geometry>
        </collision>
        <visual>
            <origin rpy="0.0 0 0" xyz="0 0 0.005"/>
            <geometry>
                <mesh filename="package://jibo_robot_description/models/jibo/meshes/jibo_final_parts_waist_v3.dae"/>
            </geometry>
            <material name="green"/>
        </visual>
	</link>

    <gazebo reference="waist_link">
        <mu1>10.0</mu1>
        <mu2>10.0</mu2>
    </gazebo>


    <joint name="fix_waist_joint" type="revolute">
    	<parent link="fix_aux_link"/>
    	<child link="waist_link"/>
        <origin xyz="0.0 0.0 0.0005" rpy="0 0.0 0.0"/>
        <limit effort="1.0" lower="-0.085" upper="0.16" velocity="0.5"/>
        <axis xyz="1 0 0"/>
	</joint>

    <gazebo>
        <plugin name="gazebo_ros_control" filename="libgazebo_ros_control.so">
        </plugin>
    </gazebo>

    <transmission name="tran2">
        <type>transmission_interface/SimpleTransmission</type>
        <joint name="fix_waist_joint">
            <hardwareInterface>EffortJointInterface</hardwareInterface>
        </joint>
        <actuator name="motor2">
            <hardwareInterface>EffortJointInterface</hardwareInterface>
            <mechanicalReduction>1</mechanicalReduction>
        </actuator>
    </transmission>

      <link name="body_link">
 	    <inertial>
            <origin xyz="0 0 0.05" rpy="0 0 0"/>
            <mass value="3" />
            <inertia ixx="0.025275" ixy="0.0" ixz="0.0" iyy="0.025275" iyz="0.0" izz="0.04335"/>
        </inertial>
        <collision>
            <origin xyz="0 0 0.05" rpy="0 0 0"/>
            <geometry>
                <cylinder length="0.17" radius="0.12"/>
            </geometry>
        </collision>
        <visual>
            <origin rpy="0.0 0 0" xyz="0 0 0.05"/>
            <geometry>
                <mesh filename="package://jibo_robot_description/models/jibo/meshes/jibo_final_parts_body_v3.dae"/>
            </geometry>
            <material name="green"/>
        </visual>
	</link>


    <joint name="waist_body_joint" type="revolute">
    	<parent link="waist_link"/>
    	<child link="body_link"/>
        <origin xyz="0.0 0.0 0.0025" rpy="-0.175 0.0 0.0"/>
        <limit effort="1.0" lower="0.0" upper="0.1" velocity="0.5"/>
	</joint>

     <gazebo>
        <plugin name="gazebo_ros_control" filename="libgazebo_ros_control.so">
        </plugin>
    </gazebo>

    <transmission name="tran3">
        <type>transmission_interface/SimpleTransmission</type>
        <joint name="waist_body_joint">
            <hardwareInterface>EffortJointInterface</hardwareInterface>
        </joint>
        <actuator name="motor3">
            <hardwareInterface>EffortJointInterface</hardwareInterface>
            <mechanicalReduction>1</mechanicalReduction>
        </actuator>
    </transmission>

    <gazebo>
        <plugin name="gazebo_ros_control" filename="libgazebo_ros_control.so">
        </plugin>
    </gazebo>




    <link name="roll_aux_link">
 	    <inertial>
            <origin xyz="0 0 0.175" rpy="0 0 0"/>
            <mass value="0.01" />
            <inertia ixx="2.64583333333e-08" ixy="0.0" ixz="0.0" iyy="2.64583333333e-08" iyz="0.0" izz="1.125e-08"/>
        </inertial>
        <collision>
            <origin xyz="0 0 0.175" rpy="0 0 0"/>
            <geometry>
                <cylinder radius="0.01" length="0.01"/>
            </geometry>
        </collision>
        <visual>
            <origin rpy="0.0 0 0" xyz="0 0 0.175"/>
            <geometry>
                <cylinder radius="0.01" length="0.01"/>
            </geometry>
            <material name="blue"/>
        </visual>
	</link>


  <joint name="waist_roll_aux_joint" type="revolute">
    	<parent link="body_link"/>
    	<child link="roll_aux_link"/>
        <origin xyz="0 0 0.01" rpy="0 0 0.0"/>
        <limit lower="-0.25" upper="0.25" effort="1.0" velocity="0.005"/>
        <axis xyz="0 1 0"/>
	</joint>


    <transmission name="tran4">
        <type>transmission_interface/SimpleTransmission</type>
        <joint name="waist_roll_aux_joint">
            <hardwareInterface>EffortJointInterface</hardwareInterface>
        </joint>
        <actuator name="motor4">
            <hardwareInterface>EffortJointInterface</hardwareInterface>
            <mechanicalReduction>1</mechanicalReduction>
        </actuator>
    </transmission>

    <link name="yaw2_aux_link">
 	    <inertial>
            <origin xyz="0 0 0.185" rpy="0 0 0"/>
            <mass value="0.01" />
            <inertia ixx="2.64583333333e-08" ixy="0.0" ixz="0.0" iyy="2.64583333333e-08" iyz="0.0" izz="1.125e-08"/>
        </inertial>
        <collision>
            <origin xyz="0 0 0.185" rpy="0 0 0"/>
            <geometry>
                <cylinder radius="0.01" length="0.01"/>
            </geometry>
        </collision>
        <visual>
            <origin rpy="0.0 0 0" xyz="0 0 0.185"/>
            <geometry>
                <cylinder radius="0.01" length="0.01"/>
            </geometry>
            <material name="blue"/>
        </visual>
	</link>


  <joint name="roll_yaw2_aux_joint" type="continuous">
    	<parent link="roll_aux_link"/>
    	<child link="yaw2_aux_link"/>
        <origin xyz="0 0 0.01" rpy="0 0 0.0"/>
        <axis xyz="0 0 1"/>
	</joint>


    <transmission name="tran5">
        <type>transmission_interface/SimpleTransmission</type>
        <joint name="roll_yaw2_aux_joint">
            <hardwareInterface>EffortJointInterface</hardwareInterface>
        </joint>
        <actuator name="motor5">
            <hardwareInterface>EffortJointInterface</hardwareInterface>
            <mechanicalReduction>1</mechanicalReduction>
        </actuator>
    </transmission>

    <link name="head_link">
 	    <inertial>
            <origin xyz="0 0 0.2" rpy="0 0 0"/>
            <mass value="5" />
            <inertia ixx="0.0338" ixy="0.0" ixz="0.0" iyy="0.0338" iyz="0.0" izz="0.0338"/>
        </inertial>
        <collision>
            <origin xyz="0 0 0.2" rpy="0 0 0"/>
            <geometry>
                <sphere radius="0.20"/>
            </geometry>
        </collision>
        <visual>
            <origin rpy="0.0 0 0" xyz="0 0 0.2"/>
            <geometry>
                <mesh filename="package://jibo_robot_description/models/jibo/meshes/jibo_final_parts_head_v5.dae"/>
            </geometry>
            <material name="blue"/>
        </visual>
	</link>


  <joint name="yaw2_aux_head_joint" type="fixed">
    	<parent link="yaw2_aux_link"/>
    	<child link="head_link"/>
        <origin xyz="0 0 0.05" rpy="0 0 0"/>
	</joint>


<!-- camera -->
  <gazebo reference="camera_link">
    <sensor type="camera" name="camera1">
      <update_rate>15.0</update_rate>
      <camera name="head">

          <pose>0 0 0.05 0 0.785 0</pose>

        <horizontal_fov>1.3962634</horizontal_fov>
        <image>
          <width>400</width>
          <height>400</height>
          <format>R8G8B8</format>
        </image>
        <clip>
          <near>0.01</near>
          <far>100</far>
        </clip>
        <noise>
          <type>gaussian</type>
          <stddev>0.007</stddev>
        </noise>
      </camera>
      <plugin name="camera_controller" filename="libgazebo_ros_camera.so">
        <alwaysOn>true</alwaysOn>
        <updateRate>0.0</updateRate>
        <cameraName>gurdy/camera1</cameraName>
        <imageTopicName>image_raw</imageTopicName>
        <cameraInfoTopicName>camera_info</cameraInfoTopicName>
        <frameName>camera_link</frameName>
        <hackBaseline>0.07</hackBaseline>
        <distortionK1>0.0</distortionK1>
        <distortionK2>0.0</distortionK2>
        <distortionK3>0.0</distortionK3>
        <distortionT1>0.0</distortionT1>
        <distortionT2>0.0</distortionT2>
      </plugin>
    </sensor>
  </gazebo>



  <!-- camera -->
  <gazebo reference="camera_link">
    <sensor type="camera" name="camera2">
      <update_rate>15.0</update_rate>
      <camera name="head">

          <pose>0 0 0.05 0 0.785 0</pose>

        <horizontal_fov>1.3962634</horizontal_fov>
        <image>
          <width>400</width>
          <height>400</height>
          <format>R8G8B8</format>
        </image>
        <clip>
          <near>0.01</near>
          <far>100</far>
        </clip>
        <noise>
          <type>gaussian</type>
          <stddev>0.007</stddev>
        </noise>
      </camera>
      <plugin name="camera_controller" filename="libgazebo_ros_camera.so">
        <alwaysOn>true</alwaysOn>
        <updateRate>0.0</updateRate>
        <cameraName>gurdy/camera1</cameraName>
        <imageTopicName>image_raw</imageTopicName>
        <cameraInfoTopicName>camera_info</cameraInfoTopicName>
        <frameName>camera_link</frameName>
        <hackBaseline>0.07</hackBaseline>
        <distortionK1>0.0</distortionK1>
        <distortionK2>0.0</distortionK2>
        <distortionK3>0.0</distortionK3>
        <distortionT1>0.0</distortionT1>
        <distortionT2>0.0</distortionT2>
      </plugin>
    </sensor>
  </gazebo>



</robot>