<robot name="jibo2">

    <gazebo>
        <plugin name="gazebo_ros_control" filename="libgazebo_ros_control.so">
        <legacyModeNS>true</legacyModeNS>
        </plugin>
    </gazebo>
	<!-- * * * Link Definitions * * * -->
    <link name="base_link">
 	    <inertial>
            <origin xyz="0 0 0" rpy="0 0 0"/>
            <mass value="2.0" />
            <inertia ixx="0.003224" ixy="0.0" ixz="0.0" iyy="0.003224" iyz="0.0" izz="0.0064"/>
        </inertial>
        <collision>
            <origin xyz="0 0 -0.006" rpy="0 0 0"/>
            <geometry>
                <cylinder radius="0.08" length="0.012"/>
            </geometry>
        </collision>
        <visual>
            <origin rpy="0.0 0 0" xyz="0 0 0"/>
            <geometry>
                <mesh filename="package://solution_jibo_description/models/jibo2/meshes/jibo_final_parts_base_v3.dae"/>
            </geometry>
        </visual>
	</link>

    <gazebo reference="base_link">
        <kp>1000000.0</kp>
        <kd>0.0</kd>
        <mu1>10.0</mu1>
        <mu2>10.0</mu2>
    </gazebo>

    <link name="waist_link">
 	    <inertial>
            <origin xyz="0 0 0" rpy="0 0 0"/>
            <mass value="0.5" />
            <inertia ixx="0.0011625" ixy="0.0" ixz="0.0" iyy="0.0011625" iyz="0.0" izz="0.002025"/>
        </inertial>
        <collision>
            <origin xyz="0 0 0.03" rpy="0 0 0"/>
            <geometry>
                <cylinder radius="0.09" length="0.06"/>
            </geometry>
        </collision>
		<visual>
            <origin rpy="0.0 0 0" xyz="0 0 0"/>
            <geometry>
                <mesh filename="package://solution_jibo_description/models/jibo2/meshes/jibo_final_parts_waist_v3.dae"/>
            </geometry>
        </visual>
	</link>

    <joint name="base_waist_joint" type="continuous">
    	<parent link="base_link"/>
    	<child link="waist_link"/>
    	<origin xyz="0 0 0" rpy="0 0 0"/>
        <limit effort="1.0" velocity="1.0"/>
        <axis xyz="0 0 1"/>
	</joint>

    <transmission name="tran1">
        <type>transmission_interface/SimpleTransmission</type>
        <joint name="base_waist_joint">
            <hardwareInterface>hardware_interface/EffortJointInterface</hardwareInterface>
        </joint>
        <actuator name="motor1">
            <hardwareInterface>EffortJointInterface</hardwareInterface>
            <mechanicalReduction>1</mechanicalReduction>
        </actuator>
    </transmission>


    <link name="body_link">
 	<inertial>
            <origin xyz="0 0 0" rpy="0 0 0"/>
            <mass value="0.5" />
            <inertia ixx="0.00166354166667" ixy="0.0" ixz="0.0" iyy="0.00166354166667" iyz="0.0" izz="0.002025"/>
        </inertial>
        <collision>
            <origin xyz="0 0 0.06" rpy="0 0 0"/>
            <geometry>
                <cylinder radius="0.09" length="0.125"/>
            </geometry>
        </collision>
		<visual>
            <origin rpy="0.0 0 0" xyz="0 0 0"/>
            <geometry>
                <mesh filename="package://solution_jibo_description/models/jibo2/meshes/jibo_final_parts_body_v3.dae"/>
            </geometry>
        </visual>
	</link>

    <joint name="waist_body_joint" type="continuous">
    	<parent link="waist_link"/>
    	<child link="body_link"/>
    	<origin xyz="0 0.006 0.052" rpy="-0.263 0 0"/>
        <limit effort="1.0" velocity="1.0"/>
        <axis xyz="0 0 1"/>
	</joint>

    <transmission name="tran2">
        <type>transmission_interface/SimpleTransmission</type>
        <joint name="waist_body_joint">
            <hardwareInterface>hardware_interface/EffortJointInterface</hardwareInterface>
        </joint>
        <actuator name="motor2">
            <hardwareInterface>EffortJointInterface</hardwareInterface>
            <mechanicalReduction>1</mechanicalReduction>
        </actuator>
    </transmission>

    <link name="head_link">
 	<inertial>
            <origin xyz="0 0 0" rpy="0 0 0"/>
            <mass value="0.1" />
            <inertia ixx="0.000625" ixy="0.0" ixz="0.0" iyy="0.000625" iyz="0.0" izz="0.000625"/>
        </inertial>
        <collision>
            <origin xyz="0 0 0" rpy="0 0 0"/>
            <geometry>
                <sphere radius="0.11"/>
            </geometry>
        </collision>
		<visual>
            <origin rpy="0.0 0 0" xyz="0 0 0"/>
            <geometry>
                <mesh filename="package://solution_jibo_description/models/jibo2/meshes/jibo_final_parts_head_v5.dae"/>
            </geometry>
        </visual>
	</link>

    <joint name="body_head_joint" type="continuous">
    	<parent link="body_link"/>
    	<child link="head_link"/>
    	<origin xyz="0 0.0 0.19" rpy="-0.4 0 0"/>
        <limit effort="1.0" velocity="1.0"/>
        <axis xyz="0 0 1"/>
	</joint>

    <transmission name="tran3">
        <type>transmission_interface/SimpleTransmission</type>
        <joint name="body_head_joint">
            <hardwareInterface>hardware_interface/EffortJointInterface</hardwareInterface>
        </joint>
        <actuator name="motor3">
            <hardwareInterface>EffortJointInterface</hardwareInterface>
            <mechanicalReduction>1</mechanicalReduction>
        </actuator>
    </transmission>


      <link name="left_wheel_link">
      	    <inertial>
		 <mass value="0.05"/>
		 <origin rpy="0 0 0" xyz="0 0 0"/>
		 <inertia ixx="3.49125e-05" ixy="0" ixz="0" iyy="3.49125e-05" iyz="0" izz="5.0625e-05"/>
	    </inertial>
	    <collision>
		<origin rpy="0 0 0" xyz="0 0 0"/>
		<geometry>
			<cylinder length="0.048" radius="0.045"/>
	    	</geometry>
	    </collision>
		<visual>
		  <origin rpy="0 0 0" xyz="0 0 0"/>
	    	  <geometry>
	          	<cylinder length="0.048" radius="0.045"/>
	    </geometry>
	      	</visual>
      </link>
    
    
      <joint name="wheel_left_joint" type="continuous">
        <origin rpy="1.5707 1.5707 1.5707" xyz="-0.1175 0 0.031"/>
        <child link="left_wheel_link"/>
        <parent link="base_link"/>
        <axis rpy="0 0 0" xyz="0 0 -1"/>
        <limit effort="10000" velocity="1000"/>
        <joint_properties damping="1.0" friction="1.0"/>
      </joint>

     <transmission name="tran4">
        <type>transmission_interface/SimpleTransmission</type>
        <joint name="wheel_left_joint">
            <hardwareInterface>hardware_interface/VelocityJointInterface</hardwareInterface>
        </joint>
        <actuator name="motor4">
            <hardwareInterface>VelocityJointInterface</hardwareInterface>
            <mechanicalReduction>7</mechanicalReduction>
        </actuator>
     </transmission>      

	
	<link name="right_wheel_link">
      	    <inertial>
		 <mass value="0.05"/>
		 <origin rpy="0 0 0" xyz="0 0 0"/>
		 <inertia ixx="3.49125e-05" ixy="0" ixz="0" iyy="3.49125e-05" iyz="0" izz="5.0625e-05"/>
	    </inertial>
	    <collision>
		<origin rpy="0 0 0" xyz="0 0 0"/>
		<geometry>
			<cylinder length="0.048" radius="0.045"/>
	    	</geometry>
	    </collision>
		<visual>
		  <origin rpy="0 0 0" xyz="0 0 0"/>
	    	  <geometry>
	          	<cylinder length="0.048" radius="0.045"/>
	    </geometry>
	      	</visual>
      </link>
    
    
    
      <joint name="wheel_right_joint" type="continuous">
        <origin rpy="1.5707 1.5707 1.5707" xyz="0.1175 0 0.031"/>
        <child link="right_wheel_link"/>
        <parent link="base_link"/>
        <axis rpy="0 0 0" xyz="0 0 -1"/>
        <limit effort="10000" velocity="1000"/>
        <joint_properties damping="1.0" friction="1.0"/>
      </joint>

    <transmission name="tran5">
        <type>transmission_interface/SimpleTransmission</type>
        <joint name="wheel_right_joint">
            <hardwareInterface>hardware_interface/VelocityJointInterface</hardwareInterface>
        </joint>
        <actuator name="motor5">
            <hardwareInterface>VelocityJointInterface</hardwareInterface>
            <mechanicalReduction>7</mechanicalReduction>
        </actuator>
     </transmission> 
    
    
     
    <link name="camera_link">
        <!-- Inertial for gazebo to take it into account, Put 1gr weight -->
        <inertial>
            <origin xyz="0 0 0" rpy="0 0 0"/>
            <mass value="0.001" />
            <inertia ixx="9.1875e-09" ixy="0.0" ixz="0.0" iyy="9.1875e-09" iyz="0.0" izz="1.378125e-08"/>
        </inertial>
		<visual>
            <origin rpy="0.0 0 0" xyz="0 0 0"/>
            <geometry>
                <box size="0.0005 0.0005 0.0005"/>
            </geometry>
            <material name="green"/>
        </visual>
	</link>

    <gazebo reference="camera_link">
        <material>Gazebo/Green</material>
    </gazebo>

    <joint name="head_camera_joint" type="fixed">
        <parent link="head_link"/>
        <child link="camera_link"/>
        <origin xyz="0.01 0.01 0.30" rpy="0 -0.75 1.5"/>
    </joint>

    <link name="camera2_link">
        <!-- Inertial for gazebo to take it into account, Put 1gr weight -->
        <inertial>
            <origin xyz="0 0 0" rpy="0 0 0"/>
            <mass value="0.001" />
            <inertia ixx="9.1875e-09" ixy="0.0" ixz="0.0" iyy="9.1875e-09" iyz="0.0" izz="1.378125e-08"/>
        </inertial>
		<visual>
            <origin rpy="0.0 0 0" xyz="0 0 0"/>
            <geometry>
                <box size="0.0005 0.0005 0.0005"/>
            </geometry>
            <material name="red"/>
        </visual>
	</link>

    <gazebo reference="camera2_link">
        <material>Gazebo/Red</material>
    </gazebo>

    <joint name="head_camera2_joint" type="fixed">
        <parent link="head_link"/>
        <child link="camera2_link"/>
        <origin xyz="0.05 0.013 0.5" rpy="0 -0.75 1.5"/>
    </joint>

    <link name="camera3_link">
        <!-- Inertial for gazebo to take it into account, Put 1gr weight -->
        <inertial>
            <origin xyz="0 0 0" rpy="0 0 0"/>
            <mass value="0.001" />
            <inertia ixx="9.1875e-09" ixy="0.0" ixz="0.0" iyy="9.1875e-09" iyz="0.0" izz="1.378125e-08"/>
        </inertial>
		<visual>
            <origin rpy="0.0 0 0" xyz="0 0 0"/>
            <geometry>
                <box size="0.0005 0.0005 0.0005"/>
            </geometry>
            <material name="red"/>
        </visual>
	</link>

    <gazebo reference="camera3_link">
        <material>Gazebo/Blue</material>
    </gazebo>

    <joint name="head_camera3_joint" type="fixed">
        <parent link="head_link"/>
        <child link="camera3_link"/>
        <origin xyz="0.09 0.08 0.19" rpy="0 -0.85 1.5"/>
    </joint>

    <!-- camera -->
  <gazebo reference="camera_link">
  <sensor name="camera" type="depth">
    <update_rate>20</update_rate>
    <camera>
	

      <horizontal_fov>1.047198</horizontal_fov>
      <image>
        <width>3000</width>
        <height>2800</height>
        <format>R8G8B8</format>
      </image>
      <clip>
        <near>0.05</near>
        <far>8</far>
      </clip>
    </camera>
    <plugin name="camera_link_controller" filename="libgazebo_ros_openni_kinect.so">
      <baseline>0.2</baseline>
      <alwaysOn>true</alwaysOn>
      <updateRate>1.0</updateRate>
      <cameraName>camera</cameraName>
      <imageTopicName>/camera/rgb/image_raw</imageTopicName>
      <cameraInfoTopicName>/camera/rgb/camera_info</cameraInfoTopicName>
      <depthImageTopicName>/camera/depth/image_raw</depthImageTopicName>
      <depthImageCameraInfoTopicName>/camera/depth/camera_info</depthImageCameraInfoTopicName>
      <pointCloudTopicName>/camera/depth/points</pointCloudTopicName>
      <frameName>camera_rgb_optical_frame</frameName>
      <pointCloudCutoff>0.5</pointCloudCutoff>
      <pointCloudCutoffMax>3.0</pointCloudCutoffMax>
      <distortionK1>0.00000001</distortionK1>
      <distortionK2>0.00000001</distortionK2>
      <distortionK3>0.00000001</distortionK3>
      <distortionT1>0.00000001</distortionT1>
      <distortionT2>0.00000001</distortionT2>
      <CxPrime>0</CxPrime>
      <Cx>0</Cx>
      <Cy>0</Cy>
      <focalLength>0</focalLength>
      <hackBaseline>0</hackBaseline>
    </plugin>
  </sensor>
</gazebo>


    <!-- camera 2-->
  <gazebo reference="camera2_link">
  <sensor name="camera2" type="depth">
    <update_rate>20</update_rate>
    <camera>
	


      <horizontal_fov>1.447198</horizontal_fov>
      <image>
        <width>640</width>
        <height>480</height>
        <format>R8G8B8</format>
      </image>
      <clip>
        <near>0.05</near>
        <far>3</far>
      </clip>
    </camera>
    <plugin name="camera2_link_controller" filename="libgazebo_ros_openni_kinect.so">
      <baseline>0.2</baseline>
      <alwaysOn>true</alwaysOn>
      <updateRate>1.0</updateRate>
      <cameraName>camera2</cameraName>
      <imageTopicName>/camera2/rgb/image_raw</imageTopicName>
      <cameraInfoTopicName>/camera2/rgb/camera_info</cameraInfoTopicName>
      <depthImageTopicName>/camera2/depth/image_raw</depthImageTopicName>
      <depthImageCameraInfoTopicName>/camera2/depth/camera_info</depthImageCameraInfoTopicName>
      <pointCloudTopicName>/camera2/depth/points</pointCloudTopicName>
      <frameName>camera2_rgb_optical_frame</frameName>
      <pointCloudCutoff>0.5</pointCloudCutoff>
      <pointCloudCutoffMax>3.0</pointCloudCutoffMax>
      <distortionK1>0.00000001</distortionK1>
      <distortionK2>0.00000001</distortionK2>
      <distortionK3>0.00000001</distortionK3>
      <distortionT1>0.00000001</distortionT1>
      <distortionT2>0.00000001</distortionT2>
      <CxPrime>0</CxPrime>
      <Cx>0</Cx>
      <Cy>0</Cy>
      <focalLength>0</focalLength>
      <hackBaseline>0</hackBaseline>
    </plugin>
  </sensor>
</gazebo>

  <!-- camera 3 -->
  <gazebo reference="camera3_link">
  <sensor name="camera3" type="depth">
    <update_rate>20</update_rate>
    <camera>
	

      <horizontal_fov>1.047198</horizontal_fov>
      <image>
        <width>640</width>
        <height>480</height>
        <format>R8G8B8</format>
      </image>
      <clip>
        <near>0.05</near>
        <far>3</far>
      </clip>
    </camera>
    <plugin name="camera3_link_controller" filename="libgazebo_ros_openni_kinect.so">
      <baseline>0.2</baseline>
      <alwaysOn>true</alwaysOn>
      <updateRate>1.0</updateRate>
      <cameraName>camera3</cameraName>
      <imageTopicName>/camera3/rgb/image_raw</imageTopicName>
      <cameraInfoTopicName>/camera3/rgb/camera_info</cameraInfoTopicName>
      <depthImageTopicName>/camera3/depth/image_raw</depthImageTopicName>
      <depthImageCameraInfoTopicName>/camera3/depth/camera_info</depthImageCameraInfoTopicName>
      <pointCloudTopicName>/camera3/depth/points</pointCloudTopicName>
      <frameName>camera3_rgb_optical_frame</frameName>
      <pointCloudCutoff>0.5</pointCloudCutoff>
      <pointCloudCutoffMax>3.0</pointCloudCutoffMax>
      <distortionK1>0.00000001</distortionK1>
      <distortionK2>0.00000001</distortionK2>
      <distortionK3>0.00000001</distortionK3>
      <distortionT1>0.00000001</distortionT1>
      <distortionT2>0.00000001</distortionT2>
      <CxPrime>0</CxPrime>
      <Cx>0</Cx>
      <Cy>0</Cy>
      <focalLength>0</focalLength>
      <hackBaseline>0</hackBaseline>
    </plugin>
  </sensor>
</gazebo>

  <! -- Diff - Wheels -->
 
  <gazebo>
   <plugin name="differential_drive_controller" filename="libgazebo_ros_diff_drive.so">
     <alwaysOn>true</alwaysOn>
     <legacyMode>false</legacyMode>
     <updateRate>100</updateRate>
     <robotNamespace>/</robotNamespace>
     <leftJoint>wheel_left_joint</leftJoint>
     <rightJoint>wheel_right_joint</rightJoint>
     <wheelSeparation>0.235</wheelSeparation>
     <wheelDiameter>0.04</wheelDiameter>
     <torque>0.1</torque>
     <commandTopic>cmd_vel</commandTopic>
     <odometryTopic>odom</odometryTopic>
     <odometryFrame>odom</odometryFrame>
     <odometrySource>world</odometrySource>
     <publishTf>1</publishTf>
     <rosDebugLevel>na</rosDebugLevel>
     <wheelAcceleration>0</wheelAcceleration>
     <wheelTorque>5</wheelTorque>
     <robotBaseFrame>base_link</robotBaseFrame>
     <publishWheelTF>false</publishWheelTF>
     <publishWheelJointState>false</publishWheelJointState>
      <publishOdomTF>true</publishOdomTF>
   </plugin>
</gazebo>


  <gazebo reference="left_wheel_link">
	<material>
	  Gazebo/Black
	</material>
  </gazebo>

  <gazebo reference="right_wheel_link">
	<material>
	  Gazebo/Black
	</material>
  </gazebo>

  <!-- APAGAR ESSA PARTE DO PLUGIN DE LED PRA RODAR NORMAL NO GAZEBO ENQUANTO NAO AJUSTAR A DEPENDENCIA IGNITION MATH6 DO OSRF -->
  <! -- Led Plugin -->

    <gazebo>
  <model name='light_model'>
    <pose>0 0 0.5 0 0 0</pose>
    <link name='light_link'>
      <visual name='light_source'>
        <pose>0 0 0 0 0 0</pose>
        <geometry>
          <sphere>
            <radius>0.025</radius>
          </sphere>
        </geometry>
        <material>
          <ambient>1 1 1 1</ambient>
          <diffuse>1 1 1 1</diffuse>
          <specular>1 1 1 1</specular>
          <emissive>0 0 0 1</emissive>
        </material>
      </visual>
      <light name='light_source' type='point'>
        <pose>0 0 0 0 0 0</pose>
        <attenuation>
          <range>0.20</range>
          <linear>0.10</linear>
        </attenuation>
        <diffuse>0 0 0 1</diffuse>
        <specular>0 0 0 1</specular>
      </light>
    </link>
    <plugin name='light_control' filename='libRosFlashLightPlugin.so'>
      <service_name>enable</service_name>
      <light>
        <id>light_link/light_source</id>
        <enable>false</enable>
        <duration>1</duration>
        <interval>0</interval>
        <color>1 1 1</color>
      </light>
    </plugin>
  </model>
</gazebo>

<gazebo>
  <joint name='light_joint' type='fixed'>
    <parent>head_link</parent>
    <child>light_model::light_link</child>
  </joint>
</gazebo>

</robot>
