<robot name="jibo2">

    <gazebo>
        <plugin name="gazebo_ros_control" filename="libgazebo_ros_control.so">
        <legacyModeNS>true</legacyModeNS>
        </plugin>
    </gazebo>
	<!-- * * * Link Definitions * * * -->
    <link name="base_link">
 	    <inertial>
            <origin xyz="0 0 0" rpy="0 0 0"/>
            <mass value="2.0" />
            <inertia ixx="0.003224" ixy="0.0" ixz="0.0" iyy="0.003224" iyz="0.0" izz="0.0064"/>
        </inertial>
        <collision>
            <origin xyz="0 0 -0.006" rpy="0 0 0"/>
            <geometry>
                <cylinder radius="0.08" length="0.012"/>
            </geometry>
        </collision>
        <visual>
            <origin rpy="0.0 0 0" xyz="0 0 0"/>
            <geometry>
                <mesh filename="package://solution_jibo_description/models/jibo2/meshes/jibo_final_parts_base_v3.dae"/>
            </geometry>
        </visual>
	</link>

    <gazebo reference="base_link">
        <kp>1000000.0</kp>
        <kd>0.0</kd>
        <mu1>10.0</mu1>
        <mu2>10.0</mu2>
    </gazebo>

    <link name="waist_link">
 	    <inertial>
            <origin xyz="0 0 0" rpy="0 0 0"/>
            <mass value="0.5" />
            <inertia ixx="0.0011625" ixy="0.0" ixz="0.0" iyy="0.0011625" iyz="0.0" izz="0.002025"/>
        </inertial>
        <collision>
            <origin xyz="0 0 0.03" rpy="0 0 0"/>
            <geometry>
                <cylinder radius="0.09" length="0.06"/>
            </geometry>
        </collision>
		<visual>
            <origin rpy="0.0 0 0" xyz="0 0 0"/>
            <geometry>
                <mesh filename="package://solution_jibo_description/models/jibo2/meshes/jibo_final_parts_waist_v3.dae"/>
            </geometry>
        </visual>
	</link>

    <joint name="base_waist_joint" type="continuous">
    	<parent link="base_link"/>
    	<child link="waist_link"/>
    	<origin xyz="0 0 0" rpy="0 0 0"/>
        <limit effort="1.0" velocity="1.0"/>
        <axis xyz="0 0 1"/>
	</joint>

    <transmission name="tran1">
        <type>transmission_interface/SimpleTransmission</type>
        <joint name="base_waist_joint">
            <hardwareInterface>EffortJointInterface</hardwareInterface>
        </joint>
        <actuator name="motor1">
            <hardwareInterface>EffortJointInterface</hardwareInterface>
            <mechanicalReduction>1</mechanicalReduction>
        </actuator>
    </transmission>


    <link name="body_link">
 	    <inertial>
            <origin xyz="0 0 0" rpy="0 0 0"/>
            <mass value="0.5" />
            <inertia ixx="0.00166354166667" ixy="0.0" ixz="0.0" iyy="0.00166354166667" iyz="0.0" izz="0.002025"/>
        </inertial>
        <collision>
            <origin xyz="0 0 0.06" rpy="0 0 0"/>
            <geometry>
                <cylinder radius="0.09" length="0.125"/>
            </geometry>
        </collision>
		<visual>
            <origin rpy="0.0 0 0" xyz="0 0 0"/>
            <geometry>
                <mesh filename="package://solution_jibo_description/models/jibo2/meshes/jibo_final_parts_body_v3.dae"/>
            </geometry>
        </visual>
	</link>

    <joint name="waist_body_joint" type="continuous">
    	<parent link="waist_link"/>
    	<child link="body_link"/>
    	<origin xyz="0 0.006 0.052" rpy="-0.263 0 0"/>
        <limit effort="1.0" velocity="1.0"/>
        <axis xyz="0 0 1"/>
	</joint>

    <transmission name="tran2">
        <type>transmission_interface/SimpleTransmission</type>
        <joint name="waist_body_joint">
            <hardwareInterface>EffortJointInterface</hardwareInterface>
        </joint>
        <actuator name="motor2">
            <hardwareInterface>EffortJointInterface</hardwareInterface>
            <mechanicalReduction>1</mechanicalReduction>
        </actuator>
    </transmission>

    <link name="head_link">
 	    <inertial>
            <origin xyz="0 0 0" rpy="0 0 0"/>
            <mass value="0.1" />
            <inertia ixx="0.000625" ixy="0.0" ixz="0.0" iyy="0.000625" iyz="0.0" izz="0.000625"/>
        </inertial>
        <collision>
            <origin xyz="0 0 0" rpy="0 0 0"/>
            <geometry>
                <sphere radius="0.11"/>
            </geometry>
        </collision>
		<visual>
            <origin rpy="0.0 0 0" xyz="0 0 0"/>
            <geometry>
                <mesh filename="package://solution_jibo_description/models/jibo2/meshes/jibo_final_parts_head_v5.dae"/>
            </geometry>
        </visual>
	</link>

    <joint name="body_head_joint" type="continuous">
    	<parent link="body_link"/>
    	<child link="head_link"/>
    	<origin xyz="0 0.0 0.19" rpy="-0.4 0 0"/>
        <limit effort="1.0" velocity="1.0"/>
        <axis xyz="0 0 1"/>
	</joint>

    <transmission name="tran3">
        <type>transmission_interface/SimpleTransmission</type>
        <joint name="body_head_joint">
            <hardwareInterface>EffortJointInterface</hardwareInterface>
        </joint>
        <actuator name="motor3">
            <hardwareInterface>EffortJointInterface</hardwareInterface>
            <mechanicalReduction>1</mechanicalReduction>
        </actuator>
    </transmission>


     
    <link name="camera_link">
        <!-- Inertial for gazebo to take it into account, Put 1gr weight -->
        <inertial>
            <origin xyz="0 0 0" rpy="0 0 0"/>
            <mass value="0.001" />
            <inertia ixx="9.1875e-09" ixy="0.0" ixz="0.0" iyy="9.1875e-09" iyz="0.0" izz="1.378125e-08"/>
        </inertial>
		<visual>
            <origin rpy="0.0 0 0" xyz="0 0 0"/>
            <geometry>
                <box size="0.0005 0.0005 0.0005"/>
            </geometry>
            <material name="green"/>
        </visual>
	</link>

    <gazebo reference="camera_link">
        <material>Gazebo/Green</material>
    </gazebo>

    <joint name="head_camera_joint" type="fixed">
        <parent link="head_link"/>
        <child link="camera_link"/>
        <origin xyz="0.01 0.01 0.30" rpy="0 -0.75 1.5"/>
    </joint>

    <link name="camera2_link">
        <!-- Inertial for gazebo to take it into account, Put 1gr weight -->
        <inertial>
            <origin xyz="0 0 0" rpy="0 0 0"/>
            <mass value="0.001" />
            <inertia ixx="9.1875e-09" ixy="0.0" ixz="0.0" iyy="9.1875e-09" iyz="0.0" izz="1.378125e-08"/>
        </inertial>
		<visual>
            <origin rpy="0.0 0 0" xyz="0 0 0"/>
            <geometry>
                <box size="0.0005 0.0005 0.0005"/>
            </geometry>
            <material name="red"/>
        </visual>
	</link>

    <gazebo reference="camera2_link">
        <material>Gazebo/Red</material>
    </gazebo>

    <joint name="head_camera2_joint" type="fixed">
        <parent link="head_link"/>
        <child link="camera2_link"/>
        <origin xyz="0.05 0.013 0.5" rpy="0 -0.75 1.5"/>
    </joint>

    <link name="camera3_link">
        <!-- Inertial for gazebo to take it into account, Put 1gr weight -->
        <inertial>
            <origin xyz="0 0 0" rpy="0 0 0"/>
            <mass value="0.001" />
            <inertia ixx="9.1875e-09" ixy="0.0" ixz="0.0" iyy="9.1875e-09" iyz="0.0" izz="1.378125e-08"/>
        </inertial>
		<visual>
            <origin rpy="0.0 0 0" xyz="0 0 0"/>
            <geometry>
                <box size="0.0005 0.0005 0.0005"/>
            </geometry>
            <material name="red"/>
        </visual>
	</link>

    <gazebo reference="camera3_link">
        <material>Gazebo/Blue</material>
    </gazebo>

    <joint name="head_camera3_joint" type="fixed">
        <parent link="head_link"/>
        <child link="camera3_link"/>
        <origin xyz="0.09 0.08 0.19" rpy="0 -0.85 1.5"/>
    </joint>

    <!-- camera -->
  <gazebo reference="camera_link">
  <sensor name="camera" type="depth">
    <update_rate>20</update_rate>
    <camera>
	

      <horizontal_fov>1.047198</horizontal_fov>
      <image>
        <width>3000</width>
        <height>2800</height>
        <format>R8G8B8</format>
      </image>
      <clip>
        <near>0.05</near>
        <far>8</far>
      </clip>
    </camera>
    <plugin name="camera_link_controller" filename="libgazebo_ros_openni_kinect.so">
      <baseline>0.2</baseline>
      <alwaysOn>true</alwaysOn>
      <updateRate>1.0</updateRate>
      <cameraName>camera</cameraName>
      <imageTopicName>/camera/rgb/image_raw</imageTopicName>
      <cameraInfoTopicName>/camera/rgb/camera_info</cameraInfoTopicName>
      <depthImageTopicName>/camera/depth/image_raw</depthImageTopicName>
      <depthImageCameraInfoTopicName>/camera/depth/camera_info</depthImageCameraInfoTopicName>
      <pointCloudTopicName>/camera/depth/points</pointCloudTopicName>
      <frameName>camera_rgb_optical_frame</frameName>
      <pointCloudCutoff>0.5</pointCloudCutoff>
      <pointCloudCutoffMax>3.0</pointCloudCutoffMax>
      <distortionK1>0.00000001</distortionK1>
      <distortionK2>0.00000001</distortionK2>
      <distortionK3>0.00000001</distortionK3>
      <distortionT1>0.00000001</distortionT1>
      <distortionT2>0.00000001</distortionT2>
      <CxPrime>0</CxPrime>
      <Cx>0</Cx>
      <Cy>0</Cy>
      <focalLength>0</focalLength>
      <hackBaseline>0</hackBaseline>
    </plugin>
  </sensor>
</gazebo>


    <!-- camera 2-->
  <gazebo reference="camera2_link">
  <sensor name="camera2" type="depth">
    <update_rate>20</update_rate>
    <camera>
	


      <horizontal_fov>1.447198</horizontal_fov>
      <image>
        <width>640</width>
        <height>480</height>
        <format>R8G8B8</format>
      </image>
      <clip>
        <near>0.05</near>
        <far>3</far>
      </clip>
    </camera>
    <plugin name="camera2_link_controller" filename="libgazebo_ros_openni_kinect.so">
      <baseline>0.2</baseline>
      <alwaysOn>true</alwaysOn>
      <updateRate>1.0</updateRate>
      <cameraName>camera2</cameraName>
      <imageTopicName>/camera2/rgb/image_raw</imageTopicName>
      <cameraInfoTopicName>/camera2/rgb/camera_info</cameraInfoTopicName>
      <depthImageTopicName>/camera2/depth/image_raw</depthImageTopicName>
      <depthImageCameraInfoTopicName>/camera2/depth/camera_info</depthImageCameraInfoTopicName>
      <pointCloudTopicName>/camera2/depth/points</pointCloudTopicName>
      <frameName>camera2_rgb_optical_frame</frameName>
      <pointCloudCutoff>0.5</pointCloudCutoff>
      <pointCloudCutoffMax>3.0</pointCloudCutoffMax>
      <distortionK1>0.00000001</distortionK1>
      <distortionK2>0.00000001</distortionK2>
      <distortionK3>0.00000001</distortionK3>
      <distortionT1>0.00000001</distortionT1>
      <distortionT2>0.00000001</distortionT2>
      <CxPrime>0</CxPrime>
      <Cx>0</Cx>
      <Cy>0</Cy>
      <focalLength>0</focalLength>
      <hackBaseline>0</hackBaseline>
    </plugin>
  </sensor>
</gazebo>

  <!-- camera 3 -->
  <gazebo reference="camera3_link">
  <sensor name="camera3" type="depth">
    <update_rate>20</update_rate>
    <camera>
	

      <horizontal_fov>1.047198</horizontal_fov>
      <image>
        <width>640</width>
        <height>480</height>
        <format>R8G8B8</format>
      </image>
      <clip>
        <near>0.05</near>
        <far>3</far>
      </clip>
    </camera>
    <plugin name="camera3_link_controller" filename="libgazebo_ros_openni_kinect.so">
      <baseline>0.2</baseline>
      <alwaysOn>true</alwaysOn>
      <updateRate>1.0</updateRate>
      <cameraName>camera3</cameraName>
      <imageTopicName>/camera3/rgb/image_raw</imageTopicName>
      <cameraInfoTopicName>/camera3/rgb/camera_info</cameraInfoTopicName>
      <depthImageTopicName>/camera3/depth/image_raw</depthImageTopicName>
      <depthImageCameraInfoTopicName>/camera3/depth/camera_info</depthImageCameraInfoTopicName>
      <pointCloudTopicName>/camera3/depth/points</pointCloudTopicName>
      <frameName>camera3_rgb_optical_frame</frameName>
      <pointCloudCutoff>0.5</pointCloudCutoff>
      <pointCloudCutoffMax>3.0</pointCloudCutoffMax>
      <distortionK1>0.00000001</distortionK1>
      <distortionK2>0.00000001</distortionK2>
      <distortionK3>0.00000001</distortionK3>
      <distortionT1>0.00000001</distortionT1>
      <distortionT2>0.00000001</distortionT2>
      <CxPrime>0</CxPrime>
      <Cx>0</Cx>
      <Cy>0</Cy>
      <focalLength>0</focalLength>
      <hackBaseline>0</hackBaseline>
    </plugin>
  </sensor>
</gazebo>




</robot>
