<robot name="jibo">

    <material name="blue">
        <color rgba="0 0 0.8 1"/>
    </material>
    <material name="red">
        <color rgba="0.8 0 0 1"/>
    </material>
    <material name="green">
        <color rgba="0 0.8 0 1"/>
    </material>
	<!-- * * * Link Definitions * * * -->

    <link name="base_link">
        <inertial>
            <origin xyz="0 0 0.02" rpy="0 0 0"/>
            <mass value="2" />
            <inertia ixx="7.58333333333e-07" ixy="0.0" ixz="0.0" iyy="7.58333333333e-07" iyz="0.0" izz="1.25e-06"/>
        </inertial>
        <collision>
            <origin xyz="0 0 0" rpy="0 0 0"/>
            <geometry>
                <cylinder radius="0.15" length="0.05"/>
            </geometry>
        </collision>
		<visual>
		    <origin xyz="0 0 0.01" rpy="0 0 0"/>
			<geometry>
				<mesh filename="package://jibo_robot_description/models/jibo/meshes/jibo_final_parts_base_v3.dae"/>
			</geometry>
		</visual>
	</link>

    <link name="waist_link">
 	    <inertial>
            <origin xyz="0 0 0.02" rpy="0 0 0"/>
            <mass value="2" />
            <inertia ixx="7.58333333333e-07" ixy="0.0" ixz="0.0" iyy="7.58333333333e-07" iyz="0.0" izz="1.25e-06"/>
        </inertial>
        <collision>
            <origin xyz="0 0 0.02" rpy="0 0 0"/>
            <geometry>
                <cylinder radius="0.16" length="0.07"/>
            </geometry>
        </collision>
        <visual>
            <origin rpy="0.0 0 0" xyz="0 0 0"/>
            <geometry>
                <mesh filename="package://jibo_robot_description/models/jibo/meshes/jibo_final_parts_waist_v3.dae"/>
            </geometry>
        </visual>
	</link>

    <gazebo reference="waist_link">
        <mu1>10.0</mu1>
        <mu2>10.0</mu2>
    </gazebo>

    <joint name="fixed" type="fixed">
        <parent link="base_link"/>
        <child link="waist_link"/>
    </joint>


    <link name="body_link">
 	    <inertial>
            <origin xyz="0 0 0.05" rpy="0 0 0"/>
            <mass value="3" />
            <inertia ixx="3.01322916667e-06" ixy="0.0" ixz="0.0" iyy="3.01322916667e-06" iyz="0.0" izz="5.625e-09"/>
        </inertial>
        <collision>
            <origin xyz="0 0 0.05" rpy="0 0 0"/>
            <geometry>
                <cylinder length="0.17" radius="0.12"/>
            </geometry>
        </collision>
        <visual>
            <origin rpy="0.0 0 0" xyz="0 0 0"/>
            <geometry>
                <mesh filename="package://jibo_robot_description/models/jibo/meshes/jibo_final_parts_body_v3.dae"/>
            </geometry>
            <material name="green"/>
        </visual>
	</link>


    <joint name="waist_joint" type="continuous">
    	<parent link="waist_link"/>
    	<child link="body_link"/>
        <origin xyz="0.0 0.0 0.051" rpy="0.0 0.785 0.0"/>
	</joint>


    <gazebo>
        <plugin name="gazebo_ros_control" filename="libgazebo_ros_control.so">
        </plugin>
    </gazebo>

    <transmission name="tran1">
        <type>transmission_interface/SimpleTransmission</type>
        <joint name="wilst_joint">
            <hardwareInterface>EffortJointInterface</hardwareInterface>
        </joint>
        <actuator name="motor1">
            <hardwareInterface>EffortJointInterface</hardwareInterface>
            <mechanicalReduction>1</mechanicalReduction>
        </actuator>
    </transmission>


  <link name="roll_aux_link">
 	    <inertial>
            <origin xyz="0 0 0.0285" rpy="0 0 0"/>
            <mass value="0.01" />
            <inertia ixx="2.64583333333e-08" ixy="0.0" ixz="0.0" iyy="2.64583333333e-08" iyz="0.0" izz="1.125e-08"/>
        </inertial>
        <collision>
            <origin xyz="0 0 0.00285" rpy="0 0 0"/>
            <geometry>
                <cylinder radius="0.01" length="0.01"/>
            </geometry>
        </collision>
        <visual>
            <origin rpy="0.0 0 0" xyz="0 0 0"/>
            <geometry>
                <cylinder radius="0.01" length="0.01"/>
            </geometry>
            <material name="blue"/>
        </visual>
	</link>


  <joint name="waist_roll_aux_joint" type="revolute">
    	<parent link="waist_link"/>
    	<child link="roll_aux_link"/>
        <origin xyz="-0.02165 -0.0125 -0.008" rpy="3.14159 0 0.523599"/>
        <limit lower="-1.55" upper="1.55" effort="1.0" velocity="0.005"/>
        <axis xyz="1 0 0"/>
	</joint>


    <transmission name="tran2">
        <type>transmission_interface/SimpleTransmission</type>
        <joint name="waist_roll_aux_joint">
            <hardwareInterface>EffortJointInterface</hardwareInterface>
        </joint>
        <actuator name="motor2">
            <hardwareInterface>EffortJointInterface</hardwareInterface>
            <mechanicalReduction>1</mechanicalReduction>
        </actuator>
    </transmission>

<link name="pitch_aux_link">
 	    <inertial>
            <origin xyz="0 0 0.0285" rpy="0 0 0"/>
            <mass value="0.01" />
            <inertia ixx="2.64583333333e-08" ixy="0.0" ixz="0.0" iyy="2.64583333333e-08" iyz="0.0" izz="1.125e-08"/>
        </inertial>
        <collision>
            <origin xyz="0 0 0.00285" rpy="0 0 0"/>
            <geometry>
                <cylinder radius="0.01" length="0.01"/>
            </geometry>
        </collision>
        <visual>
            <origin rpy="0.0 0 0" xyz="0 0 0"/>
            <geometry>
                <cylinder radius="0.01" length="0.01"/>
            </geometry>
            <material name="blue"/>
        </visual>
	</link>


  <joint name="pitch_roll_aux_joint" type="revolute">
    	<parent link="roll_aux_link"/>
    	<child link="pitch_aux_link"/>
        <origin xyz="-0.02165 -0.0125 -0.008" rpy="3.14159 0 0.523599"/>
        <limit lower="-1.55" upper="1.55" effort="1.0" velocity="0.005"/>
        <axis xyz="0 1 0"/>
	</joint>


    <transmission name="tran3">
        <type>transmission_interface/SimpleTransmission</type>
        <joint name="pitch_roll_aux_joint">
            <hardwareInterface>EffortJointInterface</hardwareInterface>
        </joint>
        <actuator name="motor3">
            <hardwareInterface>EffortJointInterface</hardwareInterface>
            <mechanicalReduction>1</mechanicalReduction>
        </actuator>
    </transmission>



  <link name="head_link">
 	    <inertial>
            <origin xyz="0 0 0.0285" rpy="0 0 0"/>
            <mass value="5" />
            <inertia ixx="2.64583333333e-08" ixy="0.0" ixz="0.0" iyy="2.64583333333e-08" iyz="0.0" izz="1.125e-08"/>
        </inertial>
        <collision>
            <origin xyz="0 0 0.00285" rpy="0 0 0"/>
            <geometry>
                <cylinder radius="0.20" length="0.26"/>
            </geometry>
        </collision>
        <visual>
            <origin rpy="0.0 0 0" xyz="0 0 0"/>
            <geometry>
                <mesh filename="package://jibo_robot_description/models/jibo/meshes/jibo_final_parts_head_v5.dae"/>
            </geometry>
            <material name="blue"/>
        </visual>
	</link>


  <joint name="pitch_aux_head_joint" type="revolute">
    	<parent link="pitch_aux_link"/>
    	<child link="head_link"/>
        <origin xyz="-0.02165 -0.0125 -0.008" rpy="3.14159 0 0.523599"/>
        <limit lower="-1.55" upper="1.55" effort="1.0" velocity="0.005"/>
        <axis xyz="0 0 1"/>
	</joint>


    <transmission name="tran4">
        <type>transmission_interface/SimpleTransmission</type>
        <joint name="pitch_aux_head_joint">
            <hardwareInterface>EffortJointInterface</hardwareInterface>
        </joint>
        <actuator name="motor4">
            <hardwareInterface>EffortJointInterface</hardwareInterface>
            <mechanicalReduction>1</mechanicalReduction>
        </actuator>
    </transmission>


<!-- camera -->
  <gazebo reference="camera_link">
    <sensor type="camera" name="camera1">
      <update_rate>15.0</update_rate>
      <camera name="head">

          <pose>0 0 0.05 0 0.785 0</pose>

        <horizontal_fov>1.3962634</horizontal_fov>
        <image>
          <width>400</width>
          <height>400</height>
          <format>R8G8B8</format>
        </image>
        <clip>
          <near>0.01</near>
          <far>100</far>
        </clip>
        <noise>
          <type>gaussian</type>
          <stddev>0.007</stddev>
        </noise>
      </camera>
      <plugin name="camera_controller" filename="libgazebo_ros_camera.so">
        <alwaysOn>true</alwaysOn>
        <updateRate>0.0</updateRate>
        <cameraName>gurdy/camera1</cameraName>
        <imageTopicName>image_raw</imageTopicName>
        <cameraInfoTopicName>camera_info</cameraInfoTopicName>
        <frameName>camera_link</frameName>
        <hackBaseline>0.07</hackBaseline>
        <distortionK1>0.0</distortionK1>
        <distortionK2>0.0</distortionK2>
        <distortionK3>0.0</distortionK3>
        <distortionT1>0.0</distortionT1>
        <distortionT2>0.0</distortionT2>
      </plugin>
    </sensor>
  </gazebo>



  <!-- camera -->
  <gazebo reference="camera_link">
    <sensor type="camera" name="camera2">
      <update_rate>15.0</update_rate>
      <camera name="head">

          <pose>0 0 0.05 0 0.785 0</pose>

        <horizontal_fov>1.3962634</horizontal_fov>
        <image>
          <width>400</width>
          <height>400</height>
          <format>R8G8B8</format>
        </image>
        <clip>
          <near>0.01</near>
          <far>100</far>
        </clip>
        <noise>
          <type>gaussian</type>
          <stddev>0.007</stddev>
        </noise>
      </camera>
      <plugin name="camera_controller" filename="libgazebo_ros_camera.so">
        <alwaysOn>true</alwaysOn>
        <updateRate>0.0</updateRate>
        <cameraName>gurdy/camera1</cameraName>
        <imageTopicName>image_raw</imageTopicName>
        <cameraInfoTopicName>camera_info</cameraInfoTopicName>
        <frameName>camera_link</frameName>
        <hackBaseline>0.07</hackBaseline>
        <distortionK1>0.0</distortionK1>
        <distortionK2>0.0</distortionK2>
        <distortionK3>0.0</distortionK3>
        <distortionT1>0.0</distortionT1>
        <distortionT2>0.0</distortionT2>
      </plugin>
    </sensor>
  </gazebo>



</robot>